<?xml version="1.0" ?>
<!-- =================================================================================== -->
<!-- |    This document was autogenerated by xacro from urdf/ur10_robot.urdf.xacro     | -->
<!-- |    EDITING THIS FILE BY HAND IS NOT RECOMMENDED                                 | -->
<!-- =================================================================================== -->
<robot name="ur10" xmlns:xacro="http://www.ros.org/wiki/xacro">
  
  
  <!-- ur10 -->
  <!-- arm -->
  <link name="world"/>
  <joint name="world_joint" type="fixed">
    <parent link="world"/>
    <child link="base_link"/>
    <origin rpy="0.0 0.0 0.0" xyz="0.0 0.0 0.0"/>
  </joint>
  <link name="base_link">
    <visual>
      <geometry>
        <mesh filename="Base.dae"/>
      </geometry>
    </visual>
    <collision>
      <origin rpy="0 0 0" xyz="0.000 0.0 0.-15"/>
      <geometry>
        <cylinder length="0.10" radius="0.085" />
        <!-- <mesh filename="Base.obj"/> -->
      </geometry>
    </collision>
    <inertial>
      <mass value="4.0"/>
      <origin rpy="0 0 0" xyz="0.0 0.0 0.0"/>
      <inertia ixx="0.0061063308908" ixy="0.0" ixz="0.0" iyy="0.0061063308908" iyz="0.0" izz="0.01125"/>
    </inertial>
  </link>
  <joint name="shoulder_pan_joint" type="revolute">
    <parent link="base_link"/>
    <child link="shoulder_link"/>
    <origin rpy="0.0 0.0 0.0" xyz="0.0 0.0 0.1273"/>
    <axis xyz="0 0 1"/>
    <limit effort="330.0" lower="-6.2831853" upper="6.2831853" velocity="2.16"/>
    <dynamics damping="0.0" friction="0.0"/>
  </joint>
  <link name="shoulder_link">
    <visual>
      <geometry>
        <mesh filename="Shoulder.dae"/>
      </geometry>
    </visual>
    <collision>
      <origin rpy="1.57079632679 0 0" xyz="0.0 0.05 -0.0"/>
      <geometry>
      <cylinder length="0.20" radius="0.044" />
      <!-- <mesh filename="Shoulder.obj"/>  -->
      
        <!-- <mesh filename="/home/robot/repos/raisim/reveal_packages/industrial_arm/scenario/models/urdf/ur_description/meshes/ur10/collision/Shoulder.dae"/> -->
      </geometry>
    </collision>
    <inertial>
      <mass value="7.778"/>
      <origin rpy="0 0 0" xyz="0.0 0.0 0.0"/>
      <inertia ixx="0.0314743125769" ixy="0.0" ixz="0.0" iyy="0.0314743125769" iyz="0.0" izz="0.021875625"/>
    </inertial>
  </link>
  <joint name="shoulder_lift_joint" type="revolute">
    <parent link="shoulder_link"/>
    <child link="upper_arm_link"/>
    <origin rpy="0.0 1.570796325 0.0" xyz="0.0 0.220941 0.0"/>
    <axis xyz="0 1 0"/>
    <limit effort="330.0" lower="-6.2831853" upper="6.2831853" velocity="2.16"/>
    <dynamics damping="0.0" friction="0.0"/>
  </joint>
  <link name="upper_arm_link">
    <visual>
      <geometry>
        <mesh filename="UpperArm.dae"/>
      </geometry>
    </visual>
    <collision>
      <origin rpy="0 0 0" xyz="0.0 -0.0500 0.320"/>
      <geometry>
        <cylinder length="0.70" radius="0.044" />
        <!-- <mesh filename="UpperArm.obj"/> -->
      </geometry>
    </collision>
    <inertial>
      <mass value="12.93"/>
      <origin rpy="0 0 0" xyz="0.0 0.0 0.306"/>
      <inertia ixx="0.421753803798" ixy="0.0" ixz="0.0" iyy="0.421753803798" iyz="0.0" izz="0.036365625"/>
    </inertial>
  </link>
  <joint name="elbow_joint" type="revolute">
    <parent link="upper_arm_link"/>
    <child link="forearm_link"/>
    <origin rpy="0.0 0.0 0.0" xyz="0.0 -0.1719 0.612"/>
    <axis xyz="0 1 0"/>
    <limit effort="150.0" lower="-6.2831853" upper="6.2831853" velocity="3.15"/>
    <dynamics damping="0.0" friction="0.0"/>
  </joint>
  <link name="forearm_link">
    <visual>
      <geometry>
        <mesh filename="Forearm.dae"/>
      </geometry>
    </visual>
    <collision>
      <!-- <origin rpy="1.57079632679 0 0" xyz="0.0 0.00 -0.0"/> -->
      <origin rpy="0 0 0" xyz="0 0.0 0.310"/>
      <geometry>
        <cylinder length="0.60" radius="0.044" />
        <!-- <mesh filename="Forearm.obj"/> -->
      </geometry>
    </collision>
    <inertial>
      <mass value="3.87"/>
      <origin rpy="0 0 0" xyz="0.0 0.0 0.28615"/>
      <inertia ixx="0.111069694097" ixy="0.0" ixz="0.0" iyy="0.111069694097" iyz="0.0" izz="0.010884375"/>
    </inertial>
  </link>
  <joint name="wrist_1_joint" type="revolute">
    <parent link="forearm_link"/>
    <child link="wrist_1_link"/>
    <origin rpy="0.0 1.570796325 0.0" xyz="0.0 0.0 0.5723"/>
    <axis xyz="0 1 0"/>
    <limit effort="54.0" lower="-6.2831853" upper="6.2831853" velocity="3.2"/>
    <dynamics damping="0.0" friction="0.0"/>
  </joint>
  <link name="wrist_1_link">
    <visual>
      <geometry>
        <mesh filename="Wrist1.dae"/>
      </geometry>
    </visual>
    <collision>
      <!-- <origin rpy="1.57079632679 0 0" xyz="0.0 0.1100 -0.0"/> -->
      <origin rpy="0 0 0" xyz="0.0 0.1100 -0.0"/>
      <geometry>
      <cylinder length="0.10" radius="0.044" />
        <!-- <mesh filename="Wrist1.obj"/> -->
      </geometry>
    </collision>
    <inertial>
      <mass value="1.96"/>
      <origin rpy="0 0 0" xyz="0.0 0.0 0.0"/>
      <inertia ixx="0.0051082479567" ixy="0.0" ixz="0.0" iyy="0.0051082479567" iyz="0.0" izz="0.0055125"/>
    </inertial>
  </link>
  <joint name="wrist_2_joint" type="revolute">
    <parent link="wrist_1_link"/>
    <child link="wrist_2_link"/>
    <origin rpy="0.0 0.0 0.0" xyz="0.0 0.1149 0.0"/>
    <axis xyz="0 0 1"/>
    <limit effort="54.0" lower="-6.2831853" upper="6.2831853" velocity="3.2"/>
    <dynamics damping="0.0" friction="0.0"/>
  </joint>
  <link name="wrist_2_link">
    <visual>
      <geometry>
        
        <mesh filename="Wrist2.dae"/>
      </geometry>
    </visual>
    <collision>
      <origin rpy="1.57079632679 0 0" xyz="0.0 0.03 0.11"/>
      
      <geometry>
      <cylinder length="0.13" radius="0.042" />
        <!-- <mesh filename="Wrist2.obj"/> -->
      </geometry>
    </collision>
    <inertial>
      <mass value="1.96"/>
      <origin rpy="0 0 0" xyz="0.0 0.0 0.0"/>
      <inertia ixx="0.0051082479567" ixy="0.0" ixz="0.0" iyy="0.0051082479567" iyz="0.0" izz="0.0055125"/>
    </inertial>
  </link>
  <joint name="wrist_3_joint" type="revolute">
    <parent link="wrist_2_link"/>
    <child link="wrist_3_link"/>
    <origin rpy="0.0 0.0 0.0" xyz="0.0 0.0 0.1157"/>
    <axis xyz="0 1 0"/>
    <limit effort="54.0" lower="-6.2831853" upper="6.2831853" velocity="3.2"/>
    <dynamics damping="0.0" friction="0.0"/>
  </joint>
  <link name="wrist_3_link">
    <visual>
      <geometry>
        <mesh filename="Wrist3.dae"/>
      </geometry>
    </visual>
    <collision>
      <origin rpy="1.57079632679 0 0" xyz="0.0 0.00 -0.0"/>
      <geometry>
        <cylinder length="0.10" radius="0.04" />
        <!-- <mesh filename="Wrist3.obj"/> -->
      </geometry>
    </collision>
    <inertial>
      <mass value="0.202"/>
      <origin rpy="0 0 0" xyz="0.0 0.0 0.0"/>
      <inertia ixx="0.000526462289415" ixy="0.0" ixz="0.0" iyy="0.000526462289415" iyz="0.0" izz="0.000568125"/>
    </inertial>
  </link>
  <joint name="ee_fixed_joint" type="fixed">
    <parent link="wrist_3_link"/>
    <child link="ee_link"/>
    <origin rpy="0.0 0.0 1.570796325" xyz="0.0 0.0922 0.0"/>
  </joint>
  <link name="ee_link"/>
    

  <joint name="g_base_joint" type="fixed">
    <parent link="ee_link"/>
    <child link="g_base"/>
    <origin rpy="0 0 -1.5708" xyz="0.0 0.0 0.0"/>
    <axis xyz="0 1 0"/>
    <limit effort="54.0" lower="-6.2831853" upper="6.2831853" velocity="3.2"/>
    <dynamics damping="0.0" friction="0.0"/>
  </joint>
  <link name="g_base">
    <visual>
      <origin xyz="0 0 0" rpy="0 0 0"/>
      <geometry>
        <mesh filename="../schunk_description/meshes/mpg_80/visual/SCHUNK_MPG-80_BASE.dae"/>
      </geometry>
    </visual>
    <collision>
      <origin xyz="0 0.035 0" rpy="0 0 0"/>
      <geometry>
        <box size="0.077 0.067 0.041"/>
      </geometry>
    </collision>
    <collision>
      <origin xyz="-0.043 0.036 0.009" rpy="0 0 0"/>
      <geometry>
        <box size="0.005 0.011 0.011"/>
      </geometry>
    </collision>
    <collision>
      <origin xyz="-0.043 0.036 -0.009" rpy="0 0 0"/>
      <geometry>
        <box size="0.006 0.012 0.012"/>
      </geometry>
    </collision>
    <inertial>
      <mass value="0.96"/>
      <origin xyz="0 0.035 0" rpy="0 0 0"/>
      <inertia ixx="0.00053312" ixy="0" ixz="0" iyy="0.00065312" iyz="0" izz="0.000904"/>
    </inertial>
  </link>
<!-- prismatic -->
  <joint name="l_finger_actuator" type="fixed"> 
    <parent link="g_base"/>
    <child link="l_finger"/>
    <origin xyz="0 0 0" rpy="0 0 0"/>
    <axis xyz="1 0 0"/>
    <limit effort="190.0" lower="0" upper="0.014" velocity="0.2333"/>
    <dynamics damping="0" friction="0"/>
  </joint>
  <link name="l_finger">
    <visual>
      <origin xyz="0 0 0" rpy="0 0 0"/>
      <geometry>
        <mesh filename="../schunk_description/meshes/mpg_80/visual/SCHUNK_MPG-80_LEFT_FINGER.dae"/>
      </geometry>
    </visual>
    <collision>
      <origin xyz="-0.0205 0.0802 0" rpy="0 0 0"/>
      <geometry>
        <box size="0.011 0.0193 0.023"/>
      </geometry>
    </collision>
    <inertial>
      <mass value="0.12"/>
      <origin xyz="-0.0205 0.0798 0" rpy="0 0 0" />
      <inertia ixx="0.0000095236" ixy="0" ixz="0" iyy="0.0000072" iyz="0" izz="0.0000052036"/>
    </inertial>
  </link>
<!-- prismatic -->
  <joint name="r_finger_actuator" type="fixed">
    <parent link="g_base"/>
    <child link="r_finger"/>
    <origin xyz="0 0 0" rpy="0 0 0"/>
    <axis xyz="1 0 0"/>
    <limit effort="190.0" lower="-0.014" upper="0" velocity="0.2333"/>
    <dynamics damping="0" friction="0"/>
  </joint>
  <link name="r_finger">
    <visual>
      <origin xyz="0 0 0" rpy="0 0 0"/>
      <geometry>
        <mesh filename="../schunk_description/meshes/mpg_80/visual/SCHUNK_MPG-80_RIGHT_FINGER.dae"/>
      </geometry>
    </visual>
    <collision>
      <origin xyz="0.0205 0.0802 0.0" rpy="0 0 0"/>
      <geometry>
        <box size="0.011 0.0193 0.023"/>
      </geometry>
    </collision>
    <inertial>
      <mass value="0.12"/>
      <origin xyz="0.0205 0.0798 0" rpy="0 0 0"/>
      <inertia ixx="0.0000095236" ixy="0" ixz="0" iyy="0.0000072" iyz="0" izz="0.0000052036"/>
    </inertial>
  </link>

  
</robot>

